Workbook

Sheet 연금시뮬레이션(260607)
A1: 종합 연금 수령 시뮬레이션 (만 59세 개시, 아파트 보유)
A3: ■ 기본 정보
A4: 항목 | B4: 값 | C4: 비고
A5: 생년월일 | B5: 1973년생 | C5: 2026년 만 53세
A6: 경제활동 | B6: 58세까지
A7: 연금 개시 나이 | B7: 만 59세 | C7: 2032년 시작
A8: 연금운용 연수익율 | B8: 0.075
A9: 연금 인출율 | B9: 0.075
A10: ISA 수익률 | B10: 0.09
A11: ISA 배당률 | B11: 0.07
A12: 예상 인플레이션 | B12: 0.025 | C12: 연평균 실질 물가상승률
B13: 100000000 | C13: =B13*4% -> 4000000
A15: ■ 주거 조건
A16: 항목 | B16: 금액 | C16: 비고
A17: 아파트 공시가격 | B17: 460000000 | C17: 6억원(6.5억원)
A18: 주택담보대출 | B18: 200000000 | C18: 2억원
A19: 대출 이자율 | B19: 0.04 | C19: 연 4%
A20: 연간 대출이자 | B20: =B18*B19 -> 8000000 | C20: 30년 상환 가정 | D20: =B20/12 -> 666666.67 | E20: 12000000 | F20: =E20/12 -> 1000000
A21: 건보료 산정 재산 | B21: =B17-B18 -> 260000000 | C21: 부채 차감 후
I22: 일 | J22: 월 | K22: 기간
H23: 실업급여 26기준 | I23: 68100 | J23: 2043000 | K23: 270 | L23: =I23*K23 -> 18387000
A24: ■ 자산 원금 및 운용 방식 (만 59세 개시일 기준)
A25: 자산 구분 | B25: 원금 | C25: 연 수익률 | D25: 연 인출률 | E25: 비고
A26: 변액유니버셜보험 | B26: =H87 -> 1.3621785e+08 | C26: =B8 -> 0.075 | D26: 0.075 | E26: 비과세
A27: 연금저축+IRP | B27: =I87 -> 1.6667919e+08 | C27: =B8 -> 0.075 | D27: 0.075 | E27: 연금소득세
A28: 퇴직연금 | B28: =J87 -> 1.7308452e+08 | C28: =B8 -> 0.075 | D28: 0.075 | E28: 연금소득세
A29: 사적연금 합계 | B29: =SUM(B26:B28) -> 4.7598156e+08 | E29: 3억원
A31: ISA (본인) | B31: =L87/2 -> 71113977 | C31: 0.09 | D31: 0.07
A32: ISA (배우자) | B32: =B31 -> 71113977 | C32: 0.09 | D32: 0.07
A33: ISA 합계 | B33: =SUM(B31:B32) -> 1.4222795e+08 | E33: ISA는 배당 아닌 커버드콜로 세금 절세
A35: ■ 국민연금 정보
A36: 수령 시기 | B36: 개시 나이 | C36: 월 수령액 | D36: 연 수령액 | E36: 조정률
A37: 조기수령 | B37: 59 | C37: 1140000 | D37: =C37*12 -> 13680000 | E37: 0.76
A38: 수령 | B38: 63 | C38: =1700000*100% -> 1700000 | D38: =C38*12 -> 20400000 | E38: 1 | F38: 62세까지 납입
A39: 윤숙 | C39: 400000 | D39: =C39*12 -> 4800000 | E39: =(D38+D39)*(1+33%) -> 33516000
A40: KR 수익 | B40: 0.14 | C40: Alternative | D40: 0.09 | E40: 아이들 | F40: 0.18 | O40: 1850000
A41: Global수익 | B41: 0.12 | C41: Pension | D41: 0.07 | O41: =O40*94% -> 1739000
J42: 내 계좌에서 | L42: 20000000 | O42: =O41*88% -> 1530320
A43: ■ 시나리오 1: 59세 조기 국민연금 - 연도별 상세
A44: 연차 | B44: 나이 | C44: 투자 총액 | E44: KRQT | H44: 변액보험잔액 | I44: 연금저축잔액 | J44: 퇴직연금잔액 | M44: 사적연금수령 | N44: ISA배당 | O44: 국민연금 | P44: 총수령액(명목) | S44: 총수령액(실질) | U44: 구매력지수 | V44: 누적실질총액
...

Sheet 연금 시뮬레이션 (3)
A1: 종합 연금 수령 시뮬레이션 (만 59세 개시, 아파트 보유)
A3: ■ 기본 정보
A4: 항목 | B4: 값 | C4: 비고
A5: 생년월일 | B5: 1973년생 | C5: 2026년 만 53세
A6: 경제활동 | B6: 58세까지
A7: 연금 개시 나이 | B7: 만 59세 | C7: 2032년 시작
A8: 연금운용 연수익율 | B8: 0.07
A9: 연금 인출율 | B9: 0.045
A10: ISA 수익률 | B10: 0.09
A11: ISA 배당률 | B11: 0.08
A12: 예상 인플레이션 | B12: 0.025 | C12: 연평균 실질 물가상승률
B13: 100000000 | C13: =B13*4% -> 4000000
A15: ■ 주거 조건
A16: 항목 | B16: 금액 | C16: 비고
A17: 아파트 공시가격 | B17: 460000000 | C17: 6억원(6.5억원)
A18: 주택담보대출 | B18: 200000000 | C18: 2억원
A19: 대출 이자율 | B19: 0.04 | C19: 연 4%
A20: 연간 대출이자 | B20: =B18*B19 -> 8000000 | C20: 30년 상환 가정 | D20: =B20/12 -> 666666.67 | E20: 12000000 | F20: =E20/12 -> 1000000
A21: 건보료 산정 재산 | B21: =B17-B18 -> 260000000 | C21: 부채 차감 후
A24: ■ 자산 원금 및 운용 방식 (만 59세 개시일 기준)
A25: 자산 구분 | B25: 원금 | C25: 연 수익률 | D25: 연 인출률 | E25: 비고
A26: 변액유니버셜보험 | B26: =H87 -> 1.4306028e+08 | C26: =B8 -> 0.07 | D26: 0.045 | E26: 비과세
A27: 연금저축+IRP | B27: =I87 -> 1.7565234e+08 | C27: =B8 -> 0.07 | D27: 0.045 | E27: 연금소득세
A28: 퇴직연금 | B28: =J87 -> 1.8214585e+08 | C28: =B8 -> 0.07 | D28: 0.045 | E28: 연금소득세
A29: 사적연금 합계 | B29: =SUM(B26:B28) -> 5.0085847e+08 | E29: 3억원
A31: ISA (본인) | B31: =L87/2 -> 75994348 | C31: 0.09 | D31: 0.08
A32: ISA (배우자) | B32: =B31 -> 75994348 | C32: 0.09 | D32: 0.08
A33: ISA 합계 | B33: =SUM(B31:B32) -> 1.519887e+08
A35: ■ 국민연금 정보
A36: 수령 시기 | B36: 개시 나이 | C36: 월 수령액 | D36: 연 수령액 | E36: 조정률
A37: 조기수령 | B37: 59 | C37: 1140000 | D37: =C37*12 -> 13680000 | E37: 0.76
A38: 2년 조기 수령 | B38: 63 | C38: =1700000*88% -> 1496000 | D38: =C38*12 -> 17952000 | E38: 0.88 | F38: 62세까지 납입
A39: 윤숙 | C39: 400000 | D39: =C39*12 -> 4800000 | E39: =D38+D39 -> 22752000
A40: KR 수익 | B40: 0.14 | C40: Alternative | D40: 0.09 | E40: 아이들 | F40: 0.18 | O40: 1850000
A41: Global수익 | B41: 0.12 | C41: Pension | D41: 0.07 | O41: =O40*94% -> 1739000
J42: 내 계좌에서 | L42: 20000000 | O42: =O41*88% -> 1530320
A43: ■ 시나리오 1: 59세 조기 국민연금 - 연도별 상세
A44: 연차 | B44: 나이 | C44: 투자 총액 | E44: KRQT | H44: 변액보험잔액 | I44: 연금저축잔액 | J44: 퇴직연금잔액 | M44: 사적연금수령 | N44: ISA배당 | O44: 국민연금 | P44: 총수령액(명목) | R44: 총수령액(실질) | T44: 구매력지수 | U44: 누적실질총액
A45: -6 | B45: 52
A46: -5 | B46: 53
...

Sheet 연금 시뮬레이션
A1: 종합 연금 수령 시뮬레이션 (만 59세 개시, 아파트 보유)
A3: ■ 기본 정보
A4: 항목 | B4: 값 | C4: 비고
A5: 생년월일 | B5: 1973년생 | C5: 2026년 만 53세
A6: 경제활동 | B6: 58세까지
A7: 연금 개시 나이 | B7: 만 59세 | C7: 2032년 시작
A8: 연금운용 연수익율 | B8: 0.065
A9: 연금 인출율 | B9: 0.05
A10: ISA 수익률 | B10: 0.07
A11: ISA 배당률 | B11: 0.04
A12: 예상 인플레이션 | B12: 0.025 | C12: 연평균 실질 물가상승률
B13: 100000000 | C13: =B13*4% -> 4000000
A15: ■ 주거 조건
A16: 항목 | B16: 금액 | C16: 비고
A17: 아파트 공시가격 | B17: 460000000 | C17: 6억원(6.5억원)
A18: 주택담보대출 | B18: 200000000 | C18: 2억원
A19: 대출 이자율 | B19: 0.04 | C19: 연 4%
A20: 연간 대출이자 | B20: =B18*B19 -> 8000000 | C20: 30년 상환 가정 | D20: =B20/12 -> 666666.67 | E20: 12000000 | F20: =E20/12 -> 1000000
A21: 건보료 산정 재산 | B21: =B17-B18 -> 260000000 | C21: 부채 차감 후
A24: ■ 자산 원금 및 운용 방식 (만 59세 개시일 기준)
A25: 자산 구분 | B25: 원금 | C25: 연 수익률 | D25: 연 인출률 | E25: 비고
A26: 변액유니버셜보험 | B26: =H89 -> 1.0651739e+08 | C26: =B8 -> 0.065 | D26: =B9 -> 0.05 | E26: 비과세
A27: 연금저축+IRP | B27: =I89 -> 4.1423619e+08 | C27: =B8 -> 0.065 | D27: =B9 -> 0.05 | E27: 연금소득세
A28: 퇴직연금 | B28: =J89 -> 1.4739539e+08 | C28: =B8 -> 0.065 | D28: =B9 -> 0.05 | E28: 연금소득세
A29: 사적연금 합계 | B29: =SUM(B26:B28) -> 6.6814897e+08 | E29: 3억원
A31: ISA 배당주 (본인) | B31: =L89/2 -> 22149000 | C31: =B10 -> 0.07 | D31: 0.05 | E31: 분리과세 9.9%
A32: ISA 배당주 (배우자) | B32: =B31 -> 22149000 | C32: =B10 -> 0.07 | D32: 0.05 | E32: 분리과세 9.9%
A33: ISA 합계 | B33: =SUM(B31:B32) -> 44298000 | E33: 총 2억원
A37: ■ 국민연금 정보
A38: 수령 시기 | B38: 개시 나이 | C38: 월 수령액 | D38: 연 수령액 | E38: 조정률
A39: 조기수령 | B39: 59 | C39: 1140000 | D39: =C39*12 -> 13680000 | E39: 0.76
A40: 정상수령 | B40: 63 | C40: 1500000 | D40: =C40*12 -> 18000000 | E40: 1
A42: KR 수익 | B42: 0.16 | C42: Alternative | D42: 0.08 | E42: 아이들 | F42: 0.15
A43: US수익 | B43: 0.12 | C43: Crypto | D43: 0.09
J44: 내 계좌에서 | L44: 20000000
A45: ■ 시나리오 1: 59세 조기 국민연금 - 연도별 상세
A46: 연차 | B46: 나이 | C46: 투자 총액 | E46: KRQT | H46: 변액보험잔액 | I46: 연금저축잔액 | J46: 퇴직연금잔액 | M46: 사적연금수령 | N46: ISA배당 | O46: 국민연금 | P46: 총수령액(명목) | R46: 총수령액(실질) | S46: 구매력지수 | T46: 누적실질총액
A47: -6 | B47: 52
A48: -5 | B48: 53
A49: -4 | B49: 54
...

Sheet 세금 및 건보료
A1: 세금 및 건강보험료 상세 분석
A3: ■ 시나리오별 연간 평균 수령액 (1년차 기준)
A4: 시나리오 | B4: 사적연금 | C4: ISA배당 | D4: 국민연금 | E4: 총 수령액
A5: 시나리오1 (59세 조기) | B5: 12000000 | C5: 8000000 | D5: ='연금 시뮬레이션'!D39 -> 13680000 | E5: =B5+C5+D5 -> 33680000
A6: 시나리오2-1 (59~62세) | B6: 12000000 | C6: 8000000 | D6: 0 | E6: =B6+C6+D6 -> 20000000
A7: 시나리오2-2 (63세~) | B7: 12000000 | C7: 8000000 | D7: ='연금 시뮬레이션'!D40 -> 18000000 | E7: =B7+C7+D7 -> 38000000
A10: ■ 세금 상세
A11: 시나리오 | B11: 사적연금소득 | C11: 국민연금소득 | D11: 연금소득합계 | E11: ISA배당 | F11: 연금소득세 | G11: ISA배당세 | H11: 총세금 | I11: 실효세율
A12: =A5 -> 시나리오1 (59세 조기) | B12: =B5 -> 12000000 | C12: =D5 -> 13680000 | D12: =B12+C12 -> 25680000 | E12: =C5 -> 8000000 | F12: =IF(D12<=12000000,D12*0.055,IF(D12<=14000000,D12*0.06,IF(D12<=50000000,D12*0.15,D12*0.24))) -> 3852000 | G12: =E12*0.099 -> 792000 | H12: =F12+G12 -> 4644000 | I12: =H12/E5 -> 0.13788599
A13: =A6 -> 시나리오2-1 (59~62세) | B13: =B6 -> 12000000 | C13: =D6 -> 0 | D13: =B13+C13 -> 12000000 | E13: =C6 -> 8000000 | F13: =IF(D13<=12000000,D13*0.055,IF(D13<=14000000,D13*0.06,IF(D13<=50000000,D13*0.15,D13*0.24))) -> 660000 | G13: =E13*0.099 -> 792000 | H13: =F13+G13 -> 1452000 | I13: =H13/E6 -> 0.0726
A14: =A7 -> 시나리오2-2 (63세~) | B14: =B7 -> 12000000 | C14: =D7 -> 18000000 | D14: =B14+C14 -> 30000000 | E14: =C7 -> 8000000 | F14: =IF(D14<=12000000,D14*0.055,IF(D14<=14000000,D14*0.06,IF(D14<=50000000,D14*0.15,D14*0.24))) -> 4500000 | G14: =E14*0.099 -> 792000 | H14: =F14+G14 -> 5292000 | I14: =H14/E7 -> 0.13926316
A17: ■ 건강보험료 (아파트 보유 조건)
A18: 재산 항목 | B18: 금액
A19: 아파트 공시가 | B19: ='연금 시뮬레이션'!B17 -> 460000000
A20: 주담대 | B20: ='연금 시뮬레이션'!B18 -> 200000000
A21: 순재산 (건보료 산정) | B21: =B19-B20 -> 260000000
A24: 시나리오 | B24: 연금소득 | C24: 소득보험료 | D24: 재산보험료 | E24: 자동차 | F24: 월건보료 | G24: 연건보료
A25: =A12 -> 시나리오1 (59세 조기) | B25: =D12 -> 25680000 | C25: =MAX(0,(D12-3360000)*0.0699/12) -> 130014 | D25: =IF($B$21<=50000000,0,IF($B$21<=90000000,($B$21-50000000)*0.0015/12,IF($B$21<=180000000,($B$21-90000000)*0.0035/12+50000/12,IF($B$21<=300000000,($B$21-180000000)*0.007/12+315000/12,IF($B$21<=600000000,($B$21-300000000)*0.011/12+1015000/12,($B$21-600000000)*0.02/12+3765000/12))))) -> 72916.667 | E25: 10990 | F25: =C25+D25+E25 -> 213920.67 | G25: =F25*12 -> 2567048
A26: =A13 -> 시나리오2-1 (59~62세) | B26: =D13 -> 12000000 | C26: =MAX(0,(D13-3360000)*0.0699/12) -> 50328 | D26: =IF($B$21<=50000000,0,IF($B$21<=90000000,($B$21-50000000)*0.0015/12,IF($B$21<=180000000,($B$21-90000000)*0.0035/12+50000/12,IF($B$21<=300000000,($B$21-180000000)*0.007/12+315000/12,IF($B$21<=600000000,($B$21-300000000)*0.011/12+1015000/12,($B$21-600000000)*0.02/12+3765000/12))))) -> 72916.667 | E26: 10990 | F26: =C26+D26+E26 -> 134234.67 | G26: =F26*12 -> 1610816
A27: =A14 -> 시나리오2-2 (63세~) | B27: =D14 -> 30000000 | C27: =MAX(0,(D14-3360000)*0.0699/12) -> 155178 | D27: =IF($B$21<=50000000,0,IF($B$21<=90000000,($B$21-50000000)*0.0015/12,IF($B$21<=180000000,($B$21-90000000)*0.0035/12+50000/12,IF($B$21<=300000000,($B$21-180000000)*0.007/12+315000/12,IF($B$21<=600000000,($B$21-300000000)*0.011/12+1015000/12,($B$21-600000000)*0.02/12+3765000/12))))) -> 72916.667 | E27: 10990 | F27: =C27+D27+E27 -> 239084.67 | G27: =F27*12 -> 2869016
A30: ■ 최종 실수령액 (연간)
A31: 시나리오 | B31: 총소득 | C31: 세금 | D31: 건보료 | E31: 대출이자 | F31: 총부담 | G31: 실수령 | H31: 월실수령 | I31: 부담률
A32: =A5 -> 시나리오1 (59세 조기) | B32: =E5 -> 33680000 | C32: =H12 -> 4644000 | D32: =G25 -> 2567048 | E32: ='연금 시뮬레이션'!B20 -> 8000000 | F32: =C32+D32+E32 -> 15211048 | G32: =B32-F32 -> 18468952 | H32: =G32/12 -> 1539079.3 | I32: =F32/B32 -> 0.45163444
A33: =A6 -> 시나리오2-1 (59~62세) | B33: =E6 -> 20000000 | C33: =H13 -> 1452000 | D33: =G26 -> 1610816 | E33: ='연금 시뮬레이션'!B20 -> 8000000 | F33: =C33+D33+E33 -> 11062816 | G33: =B33-F33 -> 8937184 | H33: =G33/12 -> 744765.33 | I33: =F33/B33 -> 0.5531408
A34: =A7 -> 시나리오2-2 (63세~) | B34: =E7 -> 38000000 | C34: =H14 -> 5292000 | D34: =G27 -> 2869016 | E34: ='연금 시뮬레이션'!B20 -> 8000000 | F34: =C34+D34+E34 -> 16161016 | G34: =B34-F34 -> 21838984 | H34: =G34/12 -> 1819915.3 | I34: =F34/B34 -> 0.42528989
A37: ■ 배우자 과세 및 건보료
A38: 항목 | B38: 금액 | C38: 세금/건보료 | D38: 비고
A39: 배우자 ISA 배당 | B39: 4000000 | C39: =B39*0.099 -> 396000 | D39: 배당세 9.9%
A40: 배우자 피부양자 여부 | B40: 탈락 가능성 높음 | C40: 별도 건보료 발생 | D40: 순재산 4억 < 5.4억이나 9억-대출2억도 체크
A42: ⚠️ 중요: 아파트 공시가 6억원인 경우
A43: - 순재산 = 6억 - 2억 = 4억원
A44: - 피부양자 기준: 재산 5.4억원 이하
A45: → 4억 < 5.4억이므로 배우자 피부양자 등록 가능 ✅
A46: → 배우자 건보료 0원 (단, ISA 배당세는 별도)
